WARNING:fake_useragent:Error occurred during loading data. Trying to use cache server https://fake-useragent.herokuapp.com/browsers/0.1.11
Traceback (most recent call last):
  File "/usr/lib/python3.8/urllib/request.py", line 1326, in do_open
    h.request(req.get_method(), req.selector, req.data, headers,
  File "/usr/lib/python3.8/http/client.py", line 1240, in request
    self._send_request(method, url, body, headers, encode_chunked)
  File "/usr/lib/python3.8/http/client.py", line 1286, in _send_request
    self.endheaders(body, encode_chunked=encode_chunked)
  File "/usr/lib/python3.8/http/client.py", line 1235, in endheaders
    self._send_output(message_body, encode_chunked=encode_chunked)
  File "/usr/lib/python3.8/http/client.py", line 1006, in _send_output
    self.send(msg)
  File "/usr/lib/python3.8/http/client.py", line 946, in send
    self.connect()
  File "/usr/lib/python3.8/http/client.py", line 917, in connect
    self.sock = self._create_connection(
  File "/usr/lib/python3.8/socket.py", line 808, in create_connection
    raise err
  File "/usr/lib/python3.8/socket.py", line 796, in create_connection
    sock.connect(sa)
socket.timeout: timed out

During handling of the above exception, another exception occurred:

Traceback (most recent call last):
  File "/usr/local/lib/python3.8/dist-packages/fake_useragent/utils.py", line 64, in get
    with contextlib.closing(urlopen(
  File "/usr/lib/python3.8/urllib/request.py", line 222, in urlopen
    return opener.open(url, data, timeout)
  File "/usr/lib/python3.8/urllib/request.py", line 525, in open
    response = self._open(req, data)
  File "/usr/lib/python3.8/urllib/request.py", line 542, in _open
    result = self._call_chain(self.handle_open, protocol, protocol +
  File "/usr/lib/python3.8/urllib/request.py", line 502, in _call_chain
    result = func(*args)
  File "/usr/lib/python3.8/urllib/request.py", line 1355, in http_open
    return self.do_open(http.client.HTTPConnection, req)
  File "/usr/lib/python3.8/urllib/request.py", line 1329, in do_open
    raise URLError(err)
urllib.error.URLError: <urlopen error timed out>

During handling of the above exception, another exception occurred:

Traceback (most recent call last):
  File "/usr/local/lib/python3.8/dist-packages/fake_useragent/utils.py", line 164, in load
    browsers_dict[browser_key] = get_browser_versions(
  File "/usr/local/lib/python3.8/dist-packages/fake_useragent/utils.py", line 120, in get_browser_versions
    html = get(
  File "/usr/local/lib/python3.8/dist-packages/fake_useragent/utils.py", line 84, in get
    raise FakeUserAgentError('Maximum amount of retries reached')
fake_useragent.errors.FakeUserAgentError: Maximum amount of retries reached
INFO:scholarly:Getting https://scholar.google.com/citations?hl=en&view_op=search_authors&mauthors=Noam%20Chomsky
INFO:scholarly:Found 1 authors
INFO:scholarly:Getting https://scholar.google.com/citations?hl=en&view_op=search_authors&mauthors=Noam%20Chomsky
INFO:scholarly:Found 1 authors
INFO:scholarly:Getting https://scholar.google.com/scholar?hl=en&q=Aspects%20of%20the%20Theory%20of%20Syntax&as_vis=0&as_sdt=0,33
INFO:scholarly:Getting https://scholar.google.com/scholar?q=info:Co-FcUN5rRUJ:scholar.google.com/&output=cite&scirp=0&hl=en
INFO:scholarly:Getting https://scholar.googleusercontent.com/scholar.bib?q=info:Co-FcUN5rRUJ:scholar.google.com/&output=citation&scisdr=CgWueqT0ELa5v8EaCUo:AAGBfm0AAAAAXzgfEUrGLLbKgerTXPJqEkPftWJ32pMv&scisig=AAGBfm0AAAAAXzgfERfFfZVheGGyB5_OWjaCNOgM6xpL&scisf=4&ct=citation&cd=-1&hl=en
